Exception in Tkinter callback
Traceback (most recent call last):
  File "c:\Users\ASUS\AppData\Local\Programs\Python\Python313\Lib\tkinter\__init__.py", line 2068, in __call__
    return self.func(*args)
           ~~~~~~~~~^^^^^^^
  File "C:\Users\ASUS\Desktop\RetailRanger\ui\dashboard.py", line 167, in <lambda>
    command=lambda i=item["name"]: self.load_module(i))
                                   ~~~~~~~~~~~~~~~~^^^
  File "C:\Users\ASUS\Desktop\RetailRanger\ui\dashboard.py", line 227, in load_module
    frame = inventory_management.InventoryManagementFrame(self.content_frame, self.controller)
  File "C:\Users\ASUS\Desktop\RetailRanger\ui\inventory_management.py", line 63, in __init__
    self.setup_categories_tab()
    ~~~~~~~~~~~~~~~~~~~~~~~~~^^
  File "C:\Users\ASUS\Desktop\RetailRanger\ui\inventory_management.py", line 1019, in setup_categories_tab
    font=FONTS["heading2"],
         ~~~~~^^^^^^^^^^^^
KeyError: 'heading2'
Exception in Tkinter callback
Traceback (most recent call last):
  File "c:\Users\ASUS\AppData\Local\Programs\Python\Python313\Lib\tkinter\__init__.py", line 2068, in __call__
    return self.func(*args)
           ~~~~~~~~~^^^^^^^
  File "C:\Users\ASUS\Desktop\RetailRanger\ui\dashboard.py", line 167, in <lambda>
    command=lambda i=item["name"]: self.load_module(i))
                                   ~~~~~~~~~~~~~~~~^^^
  File "C:\Users\ASUS\Desktop\RetailRanger\ui\dashboard.py", line 227, in load_module
    frame = inventory_management.InventoryManagementFrame(self.content_frame, self.controller)
  File "C:\Users\ASUS\Desktop\RetailRanger\ui\inventory_management.py", line 63, in __init__
    self.setup_categories_tab()
    ~~~~~~~~~~~~~~~~~~~~~~~~~^^
  File "C:\Users\ASUS\Desktop\RetailRanger\ui\inventory_management.py", line 1019, in setup_categories_tab
    font=FONTS["heading2"],
         ~~~~~^^^^^^^^^^^^
KeyError: 'heading2'
Exception in Tkinter callback
Traceback (most recent call last):
  File "c:\Users\ASUS\AppData\Local\Programs\Python\Python313\Lib\tkinter\__init__.py", line 2068, in __call__
    return self.func(*args)
           ~~~~~~~~~^^^^^^^
  File "C:\Users\ASUS\Desktop\RetailRanger\ui\dashboard.py", line 167, in <lambda>
    command=lambda i=item["name"]: self.load_module(i))
                                   ~~~~~~~~~~~~~~~~^^^
  File "C:\Users\ASUS\Desktop\RetailRanger\ui\dashboard.py", line 227, in load_module
    frame = inventory_management.InventoryManagementFrame(self.content_frame, self.controller)
  File "C:\Users\ASUS\Desktop\RetailRanger\ui\inventory_management.py", line 63, in __init__
    self.setup_categories_tab()
    ~~~~~~~~~~~~~~~~~~~~~~~~~^^
  File "C:\Users\ASUS\Desktop\RetailRanger\ui\inventory_management.py", line 1019, in setup_categories_tab
    font=FONTS["heading2"],
         ~~~~~^^^^^^^^^^^^
KeyError: 'heading2'
Exception in Tkinter callback
Traceback (most recent call last):
  File "c:\Users\ASUS\AppData\Local\Programs\Python\Python313\Lib\tkinter\__init__.py", line 2068, in __call__
    return self.func(*args)
           ~~~~~~~~~^^^^^^^
  File "C:\Users\ASUS\Desktop\RetailRanger\ui\dashboard.py", line 167, in <lambda>
    command=lambda i=item["name"]: self.load_module(i))
                                   ~~~~~~~~~~~~~~~~^^^
  File "C:\Users\ASUS\Desktop\RetailRanger\ui\dashboard.py", line 227, in load_module
    frame = inventory_management.InventoryManagementFrame(self.content_frame, self.controller)
  File "C:\Users\ASUS\Desktop\RetailRanger\ui\inventory_management.py", line 63, in __init__
    self.setup_categories_tab()
    ~~~~~~~~~~~~~~~~~~~~~~~~~^^
  File "C:\Users\ASUS\Desktop\RetailRanger\ui\inventory_management.py", line 1019, in setup_categories_tab
    font=FONTS["heading2"],
         ~~~~~^^^^^^^^^^^^
KeyError: 'heading2'
Exception in Tkinter callback
Traceback (most recent call last):
  File "c:\Users\ASUS\AppData\Local\Programs\Python\Python313\Lib\tkinter\__init__.py", line 2068, in __call__
    return self.func(*args)
           ~~~~~~~~~^^^^^^^
  File "C:\Users\ASUS\Desktop\RetailRanger\ui\dashboard.py", line 167, in <lambda>
    command=lambda i=item["name"]: self.load_module(i))
                                   ~~~~~~~~~~~~~~~~^^^
  File "C:\Users\ASUS\Desktop\RetailRanger\ui\dashboard.py", line 227, in load_module
    frame = inventory_management.InventoryManagementFrame(self.content_frame, self.controller)
  File "C:\Users\ASUS\Desktop\RetailRanger\ui\inventory_management.py", line 63, in __init__
    self.setup_categories_tab()
    ~~~~~~~~~~~~~~~~~~~~~~~~~^^
  File "C:\Users\ASUS\Desktop\RetailRanger\ui\inventory_management.py", line 1019, in setup_categories_tab
    font=FONTS["heading2"],
         ~~~~~^^^^^^^^^^^^
KeyError: 'heading2'
Exception in Tkinter callback
Traceback (most recent call last):
  File "c:\Users\ASUS\AppData\Local\Programs\Python\Python313\Lib\tkinter\__init__.py", line 2068, in __call__
    return self.func(*args)
           ~~~~~~~~~^^^^^^^
  File "C:\Users\ASUS\Desktop\RetailRanger\ui\dashboard.py", line 167, in <lambda>
    command=lambda i=item["name"]: self.load_module(i))
                                   ~~~~~~~~~~~~~~~~^^^
  File "C:\Users\ASUS\Desktop\RetailRanger\ui\dashboard.py", line 227, in load_module
    frame = inventory_management.InventoryManagementFrame(self.content_frame, self.controller)
  File "C:\Users\ASUS\Desktop\RetailRanger\ui\inventory_management.py", line 63, in __init__
    self.setup_categories_tab()
    ~~~~~~~~~~~~~~~~~~~~~~~~~^^
  File "C:\Users\ASUS\Desktop\RetailRanger\ui\inventory_management.py", line 1019, in setup_categories_tab
    font=FONTS["heading2"],
         ~~~~~^^^^^^^^^^^^
KeyError: 'heading2'
